Workbook
Name _Hlk91669107: 'REPRESENTACIÓN JUDICIAL DADEP'!$N$109
Name NativeTimeline_Data.FECHA_DE_PRESENTACION_DE_DEMANDA: #N/A

Sheet INFORME
B1: Representaciones Judiciales
C5: =Tablas!C2 -> 428 | AD5: =SUM(Consolidado!$J:$J) -> 3107916.2
C11: =Tablas!C3 -> 5
C17: =Tablas!C4 -> 1
C23: =Tablas!C5 -> 160
C29: =Tablas!C6 -> 127
C35: =Tablas!C7 -> 54
C41: =Tablas!C8 -> 81

Sheet Consolidado
A1: Name | B1: Data.ID | C1: Data.JURISDICCIÓN | D1: Data.TIPO DE PROCESO | E1: Data.FECHA DE PRESENTACION DE DEMANDA | F1: Data.ABOGADO A CARGO | G1: Data.TIPO DE REPRESENTACION DIRECTA - INDIRECTA | H1: Data.TIPO DE ZONA (CESIÓN, FISCALES, DOTACIONAL, PREDIO PÚBLICO DE NO CESIÓN, IN | I1: Data.LOCALIDAD | J1: Data.METROS CUADRADOS | K1: Data.EN CURSO - CON FALLO
A2: Tabla1 | B2: 713735 | C2: LABORAL | D2: ORDINARIO LABORAL | E2: 44267 | F2: GENARO SALAZAR GONZALEZ | G2: DIRECTA | H2: N/A | I2: SAN CRISTOBAL | J2: N/A | K2: EN CURSO
A3: Tabla1 | B3: 722198 | C3: LABORAL | D3: LABORAL | E3: 44813 | F3: GENARO SALAZAR GONZALEZ | G3: DIRECTA | H3: LABORAL | I3: CHAPINERO | J3: N/A | K3: CON FALLO
A4: Tabla1 | B4: 336186 | C4: LABORAL | D4: ORDINARIO LABORAL | E4: 40408 | F4: GENARO SALAZAR GONZALEZ | G4: DIRECTA | H4: N/A | I4: N/A | J4: NA | K4: EN CURSO
A5: Tabla1 | B5: 540276 | C5: LABORAL | D5: ORDINARIO LABORAL | E5: 42587 | F5: GENARO SALAZAR GONZALEZ | G5: DIRECTA | H5: N/A | I5: N/A | J5: NA | K5: CON FALLO
A6: Tabla1 | B6: 677535 | C6: LABORAL | D6: ORDINARIO LABORAL | E6: 43893 | F6: GENARO SALAZAR GONZALEZ | G6: DIRECTA | H6: N/A | I6: N/A | J6: N/A | K6: CON FALLO
A7: Tabla2 | B7: 16170 | C7: MASC | D7: MEDIACIÓN | E7: 45559 | F7: JOAN SEBASTIAN MARQUEZ ROJAS | G7: DIRECTA | H7: N/A | I7: N/A | J7: N/A | K7: EN CURSO
A8: Tabla3 | B8: 31038 | C8: CONSTITUCIONAL | D8: ACCION DE GRUPO | E8: 37222 | F8: MARIA FERNANDA MADIEDO SANCHEZ | G8: INDIRECTA | H8: BIENES DE USO PUBLICO | I8: SAN CRISTOBAL | J8: 10445 | K8: EN CURSO
A9: Tabla3 | B9: 167094 | C9: CONSTITUCIONAL | D9: ACCION POPULAR | E9: 37193 | F9: MARIA FERNANDA MADIEDO SANCHEZ | G9: INDIRECTA | H9: VIAS PEATONALES - VIAS VEHICULARES - ZONA VERDE - ZONA COMUNAL | I9: KENNEDY | J9: 2739 | K9: CON FALLO
A10: Tabla3 | B10: 10886 | C10: CONSTITUCIONAL | D10: ACCION POPULAR | E10: 37245 | F10: SHIRLEY AVELLANEDA PEÑA | G10: INDIRECTA | H10: RONDA - ZAMPA | I10: SUBA | J10: NA | K10: CON FALLO
A11: Tabla3 | B11: 12622 | C11: CONSTITUCIONAL | D11: ACCION POPULAR | E11: 37672 | F11: MARIA FERNANDA MADIEDO SANCHEZ | G11: INDIRECTA | H11: REMOCION EN MASA | I11: CIUDAD BOLIVAR | J11: 10465 | K11: CON FALLO
A12: Tabla3 | B12: 54949 | C12: CONSTITUCIONAL | D12: ACCION POPULAR | E12: 37930 | F12: SHIRLEY AVELLANEDA PEÑA | G12: INDIRECTA | H12: CESION | I12: SUBA | J12: 544.56 | K12: CON FALLO
A13: Tabla3 | B13: 10886 | C13: CONSTITUCIONAL | D13: ACCION POPULAR | E13: 37653 | F13: SHIRLEY AVELLANEDA PEÑA | G13: INDIRECTA | H13: BIEN DE USO PUBLICO DE NO CESION | I13: SANTAFE | J13: NA | K13: CON FALLO
A14: Tabla3 | B14: 52051 | C14: CONSTITUCIONAL | D14: ACCION POPULAR | E14: 38090 | F14: MARIA FERNANDA MADIEDO SANCHEZ | G14: INDIRECTA | H14: ZONA DE CESION | I14: KENNEDY | J14: 1516.82 | K14: CON FALLO
A15: Tabla3 | B15: 51123 | C15: CONSTITUCIONAL | D15: ACCION POPULAR | E15: 38464 | F15: MARIA FERNANDA MADIEDO SANCHEZ | G15: INDIRECTA | H15: CERRO ORIENTAL | I15: CHAPINERO | J15: NA | K15: CON FALLO
A16: Tabla3 | B16: 188832 | C16: CONSTITUCIONAL | D16: ACCION POPULAR | E16: 39020 | F16: SHIRLEY AVELLANEDA PEÑA | G16: INDIRECTA | H16: VERDE | I16: BARRIOS UNIDOS | J16: 2380.39 | K16: CON FALLO
A17: Tabla3 | B17: 167054 | C17: CONSTITUCIONAL | D17: ACCION POPULAR | E17: 38718 | F17: MARIA FERNANDA MADIEDO SANCHEZ | G17: INDIRECTA | H17: ZONA DE CESION | I17: KENNEDY | J17: 6033 | K17: CON FALLO
A18: Tabla3 | B18: 249292 | C18: CONSTITUCIONAL | D18: ACCION POPULAR | E18: 39468 | F18: MARIA FERNANDA MADIEDO SANCHEZ | G18: INDIRECTA | H18: ZONA DE CESION | I18: RAFAEL URIBE | J18: 48728.75 | K18: CON FALLO
A19: Tabla3 | B19: 266228 | C19: CONSTITUCIONAL | D19: ACCION POPULAR | E19: 39792 | F19: MAGDA BOLENA ROJAS BALLESTEROS | G19: INDIRECTA | H19: CESION - LOTE INSTITUCIONAL | I19: KENNEDY | J19: 4903 | K19: CON FALLO
A20: Tabla3 | B20: 267029 | C20: CONSTITUCIONAL | D20: ACCION POPULAR | E20: 39814 | F20: MARIA FERNANDA MADIEDO SANCHEZ | G20: INDIRECTA | H20: ZONA DE CESION | I20: KENNEDY | J20: 22321.75 | K20: CON FALLO
A21: Tabla3 | B21: 271268 | C21: CONSTITUCIONAL | D21: ACCION POPULAR | E21: 39902 | F21: SHIRLEY AVELLANEDA PEÑA | G21: INDIRECTA | H21: CESION | I21: SUBA | J21: 647000 | K21: EN CURSO
A22: Tabla3 | B22: 285457 | C22: CONSTITUCIONAL | D22: ACCION POPULAR | E22: 39814 | F22: MARIA FERNANDA MADIEDO SANCHEZ | G22: INDIRECTA | H22: VIAS - ANDENES | I22: KENNEDY | J22: 77857.53 | K22: CON FALLO
A23: Tabla3 | B23: 324636 | C23: CONSTITUCIONAL | D23: ACCION POPULAR | E23: 40395 | F23: SHIRLEY AVELLANEDA PEÑA | G23: INDIRECTA | H23: BIENES DE USO PUBLICO | I23: BOSA | J23: 131 | K23: CON FALLO
A24: Tabla3 | B24: 332456 | C24: CONSTITUCIONAL | D24: ACCION POPULAR | E24: 40458 | F24: MARIA FERNANDA MADIEDO SANCHEZ | G24: INDIRECTA | H24: VIA VEHICULAR | I24: TEUSAQUILLO | J24: 2605.63 | K24: CON FALLO
A25: Tabla3 | B25: 334871 | C25: CONSTITUCIONAL | D25: ACCION POPULAR | E25: 40499 | F25: SHIRLEY AVELLANEDA PEÑA | G25: INDIRECTA | H25: DOTACIONAL | I25: FONTIBON | J25: NA | K25: CON FALLO
A26: Tabla3 | B26: 316655 | C26: CONSTITUCIONAL | D26: ACCION POPULAR | E26: 40380 | F26: SHIRLEY AVELLANEDA PEÑA | G26: INDIRECTA | H26: CESION | I26: MARTIRES | J26: 400 | K26: CON FALLO
A27: Tabla3 | B27: 33157 | C27: CONSTITUCIONAL | D27: ACCION POPULAR | E27: 40491 | F27: MARIA FERNANDA MADIEDO SANCHEZ | G27: INDIRECTA | H27: ZONA DE CESION | I27: KENNEDY | J27: NA | K27: CON FALLO
A28: Tabla3 | B28: 352556 | C28: CONSTITUCIONAL | D28: ACCION POPULAR | E28: 40791 | F28: MARIA FERNANDA MADIEDO SANCHEZ | G28: INDIRECTA | H28: ZONA DE CESION | I28: SUBA | J28: 3.182,00 | K28: CON FALLO
A29: Tabla3 | B29: 351749 | C29: CONSTITUCIONAL | D29: ACCION POPULAR | E29: 40560 | F29: MARIA FERNANDA MADIEDO SANCHEZ | G29: INDIRECTA | H29: BIEN DE USO PUBLICO DE NO CESION | I29: KENNEDY | J29: 1311 | K29: CON FALLO
A30: Tabla3 | B30: 359511 | C30: CONSTITUCIONAL | D30: ACCION POPULAR | E30: 40777 | F30: MARIA FERNANDA MADIEDO SANCHEZ | G30: INDIRECTA | H30: BIEN DE USO PUBLICO DE NO CESION | I30: USAQUEN | J30: NA | K30: CON FALLO
A31: Tabla3 | B31: 382225 | C31: CONSTITUCIONAL | D31: ACCION DE CUMPLIMIENTO | E31: 41116 | F31: MARIA FERNANDA MADIEDO SANCHEZ | G31: INDIRECTA | H31: CESION | I31: RAFAEL URIBE | J31: NA | K31: CON FALLO
A32: Tabla3 | B32: 346341 | C32: CONSTITUCIONAL | D32: ACCION POPULAR | E32: 40556 | F32: MARIA FERNANDA MADIEDO SANCHEZ | G32: INDIRECTA | H32: CESION | I32: SUBA | J32: 1420 | K32: CON FALLO
A33: Tabla3 | B33: 430013 | C33: CONSTITUCIONAL | D33: ACCION POPULAR | E33: 41572 | F33: MARIA FERNANDA MADIEDO SANCHEZ | G33: INDIRECTA | H33: CESION | I33: CHAPINERO | J33: 880 | K33: CON FALLO
A34: Tabla3 | B34: 417192 | C34: CONSTITUCIONAL | D34: ACCION POPULAR | E34: 41337 | F34: MARIA FERNANDA MADIEDO SANCHEZ | G34: INDIRECTA | H34: CESION | I34: CHAPINERO | J34: 8061 | K34: CON FALLO
A35: Tabla3 | B35: 454500 | C35: CONSTITUCIONAL | D35: ACCION POPULAR | E35: 41753 | F35: MARIA FERNANDA MADIEDO SANCHEZ | G35: INDIRECTA | H35: BIEN DE USO PUBLICO DE NO CESION | I35: SUBA | J35: 2647.58 | K35: CON FALLO
A36: Tabla3 | B36: 493772 | C36: CONSTITUCIONAL | D36: ACCION POPULAR | E36: 42250 | F36: MARIA FERNANDA MADIEDO SANCHEZ | G36: INDIRECTA | H36: CESION | I36: SUBA | J36: NA | K36: EN CURSO
A37: Tabla3 | B37: 492279 | C37: CONSTITUCIONAL | D37: ACCION POPULAR | E37: 42116 | F37: SHIRLEY AVELLANEDA PEÑA | G37: INDIRECTA | H37: CESION | I37: ENGATIVA | J37: 600 | K37: CON FALLO
A38: Tabla3 | B38: 498496 | C38: CONSTITUCIONAL | D38: ACCION POPULAR | E38: 42118 | F38: MARIA FERNANDA MADIEDO SANCHEZ | G38: INDIRECTA | H38: ZONA DE CESION | I38: KENNEDY | J38: 5.084,00 | K38: CON FALLO
A39: Tabla3 | B39: 526651 | C39: CONSTITUCIONAL | D39: ACCION POPULAR | E39: 42444 | F39: SHIRLEY AVELLANEDA PEÑA | G39: INDIRECTA | H39: BIEN DE USO PUBLICO DE NO CESION | I39: ENGATIVA | J39: 1842 | K39: EN CURSO
A40: Tabla3 | B40: 347551 | C40: CONSTITUCIONAL | D40: ACCION POPULAR | E40: 40590 | F40: MARIA FERNANDA MADIEDO SANCHEZ | G40: INDIRECTA | H40: ZONA DE CESION | I40: USAQUEN | J40: 1730 | K40: EN CURSO
...

Sheet REPRESENTACIÓN JUDICIAL DADEP
A1: ID | B1: JURISDICCIÓN | C1: PROCESO | D1: TIPO DE PROCESO | E1: FECHA DE PRESENTACION DE DEMANDA | F1: DESPACHO QUE ACTUALMENTE CONOCE EL PROCESO | G1: ABOGADO A CARGO | H1: DEMANDANTE / DENUNCIANTE | I1: DEMANDADO / DENUNCIADO (APELLIDOS - NOMBRES) | J1: TIPO DE REPRESENTACION DIRECTA - INDIRECTA | K1: DADEP DTE - DDO - INTERVINIENTE - COMITÉ - DENUNCIANTE | L1: TEMA PROCESO | M1: DELITO (PROCESOS PENALES) | N1: DESCRIPCION | O1: NOMBRE DE LA URBANIZACION | P1: PRETENSIONES DE LA DEMANDA EN DINERO (DADEP DEMANDANTE) | Q1: VALOR EFECTIVO RECAUDO (EJECUTIVO) (DADEP DEMANDANTE) | R1: TIPO DE ZONA (CESIÓN, FISCALES, DOTACIONAL, PREDIO PÚBLICO DE NO CESIÓN, INSTITUCIONAL) | S1: RUPI | T1: LOCALIDAD | U1: METROS CUADRADOS | V1: AVALUO CATASTRAL - COMERCIAL PREDIO | W1: % DE LA CUOTA PARTE DEL DADEP (DIVISORIOS) | X1: CONDENAS O INDEMNIZACIONES QUE EN SENTENCIA EVITARÍA LA ENTIDAD EN METROS CUADRADOS | Y1: CONDENAS O INDEMNIZACIONES QUE EN SENTENCIA EVITARÍA LA ENTIDAD EN DINERO | Z1: FECHA DE SENTENCIA EN PRIMERA INSTANCIA | AA1: FECHA DE SENTENCIA EN SEGUNDA INSTANCIA | AB1: ORDENES AL DADEP EN SENTENCIA DEFINITIVA | AC1: ACCIONES A SEGUIR | AD1: EN CURSO - CON FALLO | AE1: AREA RESPONSABLE DEL CUMPLIMIENTO | AF1: ETAPA PROCESAL | AJ1: Datos Totales
A2: 432213 | B2: CONTENCIOSO ADMINISTRATIVA | C2: 2013-02688(TRIB) - 2015-00087 (CE) 11001032400020150008700 | D2: NULIDAD SIMPLE | E2: 41598 | F2: CONSEJO DE ESTADO - SECCION PRIMERA | G2: JOAN SEBASTIAN MARQUEZ ROJAS | H2: DADEP | I2: SUPERINTENDENCIA DE NOTARIADO Y REGISTRO | J2: DIRECTA | K2: DEMANDADO | L2: DEMANDA RESOLUCIONES SUPERNOTARIADO QUE NIEGAN CIERRE DE FMI - EL CASTILLO | M2: NA | N2: DEMANDA RESOLUCIONES SUPERNOTARIADO QUE NIEGAN CIERRE DE FMI - EL CASTILLO | O2: EL CASTILLO | P2: NA | Q2: NA | R2: ZONA DE CESIÓN | S2: 381 | T2: CHAPINERO | U2: 1850 | V2: NA | W2: NA | X2: NA | Y2: NA | Z2: NA | AA2: NA | AB2: NA | AC2: FIJACIÓN DE FECHA DE AUDIENCIA INICIAL | AD2: EN CURSO | AE2: N/A | AF2: AL DESPACHO PARA FALLO | AJ2: Procesos | AK2: =(COUNTA($A:$A)+COUNTA('REPRESENTACIÓN JUDICIAL SJD'!$A:$A))-6 -> 551
A3: 164816 | B3: CIVIL | C3: 2005-01587 | D3: NULIDAD DE ESCRITURA PÚBLICA | E3: 38688 | F3: JUZGADO 72 CIVIL MUNICIPAL | G3: MARIA FERNANDA CRUZ | H3: DADEP | I3: EDGAR GARZON HERREÑO - CARLOS EDUARDO PRIETO - ELIZABETH CERON - LOS CAMPOS | J3: DIRECTA | K3: DEMANDADO | L3: NULIDAD DE EP POR OBJETO ILÍCITO | M3: NA | N3: NULIDAD DE EP POR OBJETO ILÍCITO | O3: LOS CAMPOS | P3: NA | Q3: NA | R3: ZONA DE CESIÓN | S3: 615 | T3: ENGATIVA | U3: 60 | V3: NA | W3: NA | X3: NA | Y3: NA | Z3: 41304 | AA3: NA | AB3: TRAMITAR OFICIOS ORIP Y NOTARIA | AC3: TRAMITAR LOS OFICIOS CORRESPONDIENTES | AD3: EN CURSO | AE3: N/A | AF3: SE PRESENTÓ PROCESO EJCUTIVO PARA COBRO DE COSTAS.SE DECRETA MEDIDAS CAUTELARES. | AJ3: Accion Popular | AK3: =COUNTIF($D:$D,"ACCION POPULAR")+COUNTIF('REPRESENTACIÓN JUDICIAL SJD'!$A:$AF,"ACCION POPULAR") -> 252
A4: 715785 | B4: PENAL | C4: 2022-17968 | D4: PENAL | E4: 44568 | F4: FISCALIA 136 INTERVENCIÓN TEMPRANA | G4: JOSE AGUSTÍN AVENDAÑO | H4: DADEP | I4: CONTEXTUS | J4: DIRECTA | K4: DENUNCIANTE | L4: Denuncia a Contextus SAS por conservar el bien antes entregado en contrato CAMEP | M4: ENRIQUECIMIENTO ILÍCITO DE PARTICUALRES - USURPACIÓN DE FUNCIONES PÚBLICAS - ACCESO ABUSIVO A SISTEMA INFORMÁTICO | N4: ARCHIVO PARCIAL DEL DELITO DE ACCESO ABUSIVO A SIST. INFORMÁTICO + AMPLIACIÓN DE DENUNCIA POR EL RESTO DE DELITOS- CORREO DE IMPULSO 26.09.22 Y SOLICITUD DE ACLARACIÓN DEL ARCHIVO DE AMPLIACIÓN DE DENUNCIA | O4: PARQUEADERO CENTRO COMERCIAL LA CASTELLANA | P4: N/A | Q4: N/A | R4: ZONA DE CESIÓN | S4: 4028 | T4: USAQUEN | U4: N/A | V4: N/A | W4: N/A | X4: N/A | Y4: N/A | AA4: N/A | AB4: N/A | AC4: REVISION DE SOLICITUD DE DESARCHIVO | AD4: EN CURSO | AE4: N/A | AF4: ARCHIVADO
A5: 352796 | B5: CIVIL | C5: 1990-01429 | D5: RESTITUCION DE INMUEBLE ARRENDADO | E5: 33120 | F5: JUZGADO 46 - CIVIL DEL CIRCUITO | G5: JAMMER SAUL HERNANDEZ | H5: SEC GRAL | I5: JULIO ROBERTO SILVA RUIZ Y OTRO | J5: DIRECTA | K5: INTERVINIENTE | L5: RESTITUIR BIEN FISCAL CALLE 12 5 63 | M5: NA | N5: RESTITUIR BIEN FISCAL CALLE 12 5 63 | O5: NA | P5: NA | Q5: NA | R5: BIEN FISCAL | S5: 2-518 | T5: CANDELARIA | U5: 555.5 | V5: NA | W5: NA | X5: NA | Y5: NA | Z5: NA | AA5: NA | AB5: NA | AC5: EN FECHA 30-05-2023 SE EMITE SENTENCIA FAVORABLE DE PRIMERA INSTANCIA TERMINANDO EL CONTRATO DE ARRENDAMIENTO Y ORDENANDO SU RESTITUCIÓN, SE PRESENTA RECURSO DE APLEACIÓN QUE ES RESUELTO DE MANERA FAVORABLE AL DADEP EN FECHA 22-08-2023. DESPACHO COMISORIO EN LA ALCALDIA LOCAL DE SAN CRISTÓBAL FIJA FECHA PARA ENTREGA EL 28-10-2024 | AD5: CON FALLO | AE5: N/A | AF5: SENTENCIA DE PRIMERA Y SEGUNDA INSTANCIA DEBIDAMENTE EJECUTORIADA. PENDIENTE POR DILIGENCIA DE ENTREGA DEL PREDIO POSTERIOR A LA COMISIÓN.
A6: 543680 | B6: CONSTITUCIONAL | C6: 2016-00748 | D6: ACCION POPULAR | E6: 42751 | F6: JUZGADO 50 ADMINISTRATIVO SECCION SEGUNDA DE BOGOTÁ | G6: SHIRLEY AVELLANEDA PEÑA | H6: CONJUNTO AVENIDA PARQUE PROPIEDAD HORIZONTAL | I6: ALCALDIA LOCAL DE TEUSAQUILLO, ALCALDIA MAYOR DE BOGOTÁ, DADEP Y SECRETARIA DE MOVILIDAD | J6: DIRECTA | K6: DEMANDADO | L6: OCUPACION DE ESPACIO PÚBLICO | M6: N/A | N6: SOLICITA ORDENAR A LOS DEMANDADOS EJECUTAR LAS ACCIONES TENDIENTES CON EL FIN DE EVITAR EL DAÑO CONTINGENTE Y HACER CESAR EL PELIGRO, LAS AMENAZAS Y AGRAVIO SOBRE LOS DERECHOS E INTERESES COLECTIVOS DEL GOCE DEL ESPACIO PUBLICO | O6: N/A | P6: N/A | Q6: N/A | R6: OCUPACION DE BIEN DE USO PUBLICO | S6: POR DEFINIR | T6: TEUSAQUILLO | U6: N/A | V6: N/A | W6: N/A | X6: N/A | Y6: N/A | Z6: N/A | AA6: N/A | AB6: N/A | AC6: 2017-01-30 CONTESTACIÓN DE LA DEMANDA.- 2017-02-14 AUTO QUE FIJA FECHA PARA PACTO DE CUMPLIMIENTO.- 2017-02-27 AUDIENCIA DE CONCILIACIÓN FALLIDA.- 2017-03-08 AUTO QUE DECRETA PRUEBAS.- 2017-03-23 TRASLADO ALEGATOS DE CONCLUSIÓN 1ª INSTANCIA.- 2017-03-29 PRESENTACIÓN DE ALEGATOS.- 2017-06-13 COMUNICACIÓN DE LA SENTENCIA Fallo Desfavorable 1a Instancia. "Se protege el derecho colectivo al goce del espacio público y utilización y defensa de los bines de uso público, para lo cual la Alcaldía Mayor de Bogotá, ALcaldía Local de teusaquillo, el Departamento Administrativo de la Defensoría del Espacio Púlblico y la Secretaría de Movilidad, de una parte,por intermedio de la Policía Metropolitana de Bogotá, deberán realizar los operativos mínimo cada quince (15) días con el fín de erradicar el problema de invasión del espacio público; y de otro lado, de manera coordinada esas mismas entidades en el término máximo de seis (6) meses, contados a partir de la ejecutoria de la sentencia, adelanten y lleven a su culminación el procedimiento consagrado en el artículo 8 del decreto 098 de 2004, para la recuperación del espacio público de la zona comprendida en la Calle 24 A entre carreras 59 y 60, en la ciudad de Bogotá, ocupado indebidamente. (...).- 2017-06-21 AUTO QUE ADMITE RECURSO DE APELACION. 2017-06-21 AUTO QUE ADMITE RECURSO DE APELACION Tribunal Administrativo de Cundinamarca profiere Sentencia Desfavorable en Segunda Instancia en contra de las entidades Distritales convocadas, estableciendo en la parte resolutiva del fallo : "PRIMERO. MODIFICAR el numeral tercero y ADICIONAR la Sentencia del 13 de Junio de 2017 proferida por el Juzgado Cincuenta (50) Administrativo de Bogotá, de conformidad con lo expuesto en la parte motiva de esta providencia, la cual quedará así: "(...) TERCERO: SE PROTEGE el derecho al goce del espacio público y utilización y defensa de los bienes de uso público , para lo cual la Alcaldía Mayor de Bogotá, la Alcaldía Local de Teusaquillo, el Departamento Administrativo de la Defensoría del Espacio Público y la Secretaría de Movilidad, de una parte, por intermedio de la Policía Metropolitana de Bogotá, deberán realizar operativos mínimo cada quince (15) días, por el término inicial de cuatro (4) meses y posteriormente con una menos frecuencia, con el fin de erradicar el problema de invasión del espacio público; y de otro, de manera coordinada esas mismas entidades en el término máximo de un (1) año, contado a partir de la ejecutoria de la sentencia, adelanten y lleven a su culminación el procedimiento consagrado en el artículo 8 del decreto 098 de 2004,para la recuperación del espacio público de la zona comprendida en la Calle 24 A entre carreras 59 y 60, en la ciudad de Bogotá, ocupado indebidamente. Una vez agotado el anterior procedimiento, sino no (sic) se ha podido recuperar el espacio público invadido, el Alcalde de la Localidad de Teusaquillo en uso de sus las facultades policivas consagradas en la Ley, deberá ordenar a la Policia Metropolitana de Bogotá, para que de manera insistente pero pacífica realice todas las gestiones necesarias para garantizar su restitución inmediata. Igualmente, se ordenará a las demás demandadas Alcaldía Mayor de Bogotá, DADEP y Secretaría Distrital de Movilidad, que en el marco de sus competencias, acompañen y colaboren activamente con el procedimiento administrativo para la recuperación del espacio público en la zona objeto de esta controversia, frente a los vendedores informales, así como ante los vehículos mal parqueados,. Así mismo, que cada una de las actividades que se realicen se deberá informar por escrito a este despacho. TERCERO A : INSTAR a la Alcaldía Mayor de Bogotá, la Alcaldía Local de Teusaquillo, el DADEP y la Secretaría De Movilidad para que realicen un estudio detallado de la de la problemática de la zona, y en consecuencia adopten las medidas educativas, de transito peatonal y vehicular que se analizaron en la sentencia y den solución a la situación particular de los vendedores informales, con el fin de lograr el amparo constitucional de los derechos colectivos protegidos. (...)"."2018-11-19 INFORMES. 2018-12-17 INFORMES. - 2019-04-02 INFORMES.- 2019-05-16 INFORMES.- 2019-05-24 AUTO QUE ORDENA REQUERIR.- 2019-07-18 INFORMES.- 2019-07-19 AUTO QUE ORDENA REQUERIR.- 2019-08-13 INFORMES.- 2019-09-03 INFORMES.- 2019-09-03 INFORMES.- 2020-08-03 SEGUIMIENTO CUMPLIMIENTO SENTENCIAS.- 2020-11-11INFORMES.- 2021-08-12 INFORMES.- 2022-03-03 AUTO QUE ORDENA REQUERIR.- 2022-05-05 AUTO DE TRAMITE.- 2022-07-01 PRESENTACIÓN DE INFORMES.- 2022-10-21 AUTO QUE ORDENA REQUERIR.- 2023-12-22 INFORMES.- 2024-02-28 INFORMES.- 2024-02-28 PRESENTACIÓN DE INFORMES. 23-04-2024 SE ABSTIENE DE ABRIR INCIDENTE DE DESACATO. ABRIL 24 DE 2024 NOTIFICACION POR CORREO ELECTRONICO DEL AUTO QUE PRIMERO: DECLARA EL CUMPLIMIENTO DE LA SENTENCIA DE FECHA DEL 13 DE JUNIO DE 2017- SEGUNDO:SE ABSTIENE DE CONTINUAR CON EL TRAMITE INCIDENTAL CONFORME A LA PARTE MOTIVA DEL PRESENTE AUTO. TERCERO: CONMINAR A LA ALCALDIA MAYOR DE BOGOTA , A LA ALCALDIA LOCAL DE TEUSAQUILLO, AL DEPARTAMENTO ADMINISTRATIVO DE LA DEFENSORÍA DEL ESPACIO PÚBLICO, A LA SECRETAIA DISTRITAL DE MOVILIDAD Y A LA POLICIA METROPOLITANA DE BOGOTA, PARA QUE REALICEN LAS ACTUACIONES POLICIVAS TENDIENTES A LA PROTECCION Y RESTITUCION DEL ESPACIO PUBLICO QUE SEAN NECESARIOS PARA CONSERVAR EL GOCE Y DISFRUTE DEL ESPACIO PUBLICO EN LA ZONA DE LA CALLE 24 A ENTRE CARRERAS 59 Y 60 Y OTRAS DISPOSICIONES. | AD6: CON FALLO | AE6: SGIEP | AF6: SEGUIMIENTO CUMPLIMIENTO DE FALLO CONMINACION DEL JUEZ A SEGUIR REALIZANDO OPERATIVOS EN LA ZONA OBJETO DE ACCION POPULAR.
A7: 432549 | B7: PENAL | C7: 2008-14456 | D7: PENAL | E7: 39708 | F7: FISCALIA 119 SECCIONAL UNIDAD FE PUBLICA Y ORDEN ECONOMICO - TARDÍA ABREVIADO | G7: JOSE AGUSTÍN AVENDAÑO | H7: DADEP | I7: CARLOS ALBERTO LARA ACEVEDO | J7: DIRECTA | K7: DENUNCIANTE | L7: SUPERCENTER FALSEDAD | M7: FALSEDAD EN DOCUMENTO PUBLICO - FRAUDE PROCESAL | N7: DENUNCIADO EN REPRESENTACION DE SUPERCENTER CONSTITUYE URBANIZACION SEÑALANDO QUE LAS OBRAS YA HABIAN SIDO EJECUTADAS Y QUE SE ENCONTRABA LIBRE DE EMBARGOS, NO OBSTANTE TENIA EMBARGO DE BBVA | O7: SUPERCENTER | P7: NA | Q7: NA | R7: ZONA DE CESIÓN | S7: 1355 | T7: BARRIOS UNIDOS | U7: NA | V7: NA | W7: NA | X7: NA | Y7: NA | Z7: 22/02/2016 CONDENA A 84 MESES DE PRISION | AA7: 7-3-17 CONFIRMAR PARCIALMENTE FALLO - DECLARA PRESCRIPCIÓN DELITO FALSEDAD | AB7: NA | AC7: SEGUIMIENTO PROCESAL - SEGUIMIENTO RECURSO DE CASACIÓN- CON OFICIO 44318 SE DEVUELVEN LAS DILIGENCIAS AL TRIBUNAL DEL BOGOTA EN 5 CDNOS Y 28 CD | AD7: EN CURSO | AE7: N/A | AF7: CASACION
A8: 416638 | B8: CONTENCIOSO ADMINISTRATIVA | C8: No. 25000232400020120058100 | D8: NULIDAD SIMPLE | E8: 41438 | F8: CONSEJO DE ESTADO - SECCION PRIMERA | G8: JOAN SEBASTIAN MARQUEZ ROJAS | H8: VICTOR EDUARDO DUARTE SAAVEDRA | I8: DADEP - ALCALDIA MAYOR | J8: DIRECTA | K8: DEMANDADO | L8: NULIDAD CONTRA ACTA DE TOMA DE POSESION - ANTEJARDINES MADELENA | M8: NA | N8: NULIDAD CONTRA ACTA DE TOMA DE POSESION - ANTEJARDINES MADELENA | O8: MADELENA III Y IV SECTOR | P8: NA | Q8: NA | R8: ZONA DE CESIÓN | S8: 1481 | T8: CIUDAD BOLIVAR | U8: NA | V8: NA | W8: NA | X8: 26985 | Y8: NA | Z8: 42754 | AA8: NA | AB8: NA | AC8: SEGUIMIENTO PROCESAL - ALEGATOS PRESENTADOS - PENDIENTE FALLO CONSEJO DE ESTADO. ENTRO AL DESPACHPO PARA FALLO EL 1/04/2019 - 12-08-2022 REMITEN CONSTANCIA DEL ESTADO DEL PROCESO | AD8: EN CURSO | AE8: N/A | AF8: AL DESPACHO PARA FALLO
A9: 632501 | B9: CIVIL | C9: 2015-01376 | D9: PERTENENCIA | E9: 42331 | F9: JUZGADO 42 CIVIL MUNICIPAL DE BOGOTÁ | G9: MARIA FERNANDA CRUZ | H9: GABRIEL ROJAS HUERFANO | I9: ROBERTO RODRIGUEZ ALDANA | J9: DIRECTA | K9: INTERVINIENTE | L9: PRESCRIPCION INMUEBLE POR TENER LA POSESION POR MAS DE 10 AÑOS | M9: N/A | N9: N/A | O9: VILLA EL DORADO NORTE | P9: N/A | Q9: N/A | R9: ZONA DE CESIÓN | S9: 1533 | T9: SUBA | U9: 84,50 mts2 | V9: N/A | W9: N/A | X9: N/A | Y9: N/A | Z9: N/A | AA9: N/A | AB9: N/A | AC9: EL 1 DE OCTUBRE DE 2024, ME PRONUNCIÉ FRENTE AL RECURSO DE APELACIÓN. SIN EMBARGO, EL DESPACHO NO LO HA RESUELTO. | AD9: EN CURSO | AE9: N/A | AF9: APELACIÓN
A10: 556925 | B10: CIVIL | C10: 1988-01361 11001310302019880136100 | D10: EJECUTIVO | E10: 35796 | F10: JUZGADO 5 CIVIL DE CIRCUITO DE EJECUCIÓN DE SENTENCIAS | G10: GENARO SALAZAR GONZALEZ | H10: PILAR VANEGAS - CRISTIAN RODRIGUEZ | I10: GUILLERMO MARTINEZ - SOLEDAD RAMIREZ | J10: DIRECTA | K10: INTERVINIENTE | L10: RINCON DE LOS ANGELES - EJECUTIVO CON EL CUAL SE REMATA Y ADJUDICA PREDIO | M10: NA | N10: RINCON DE LOS ANGELES - EJECUTIVO CON EL CUAL SE REMATA Y ADJUDICA PREDIO | O10: RINCON DE LOS ANGELES | P10: NA | Q10: NA | R10: ZONA DE CESIÓN | S10: 1-4875; 1-4876 | T10: KENNEDY | U10: 2600 | V10: NA | W10: NA | X10: NA | Y10: NA | Z10: 32667 | AA10: NA | AB10: SIN ORDENES AL DADEP - DADEP INTERVIENE PARA DEFENDER BIENES DEL DISTRITO | AC10: INTERVENCIÓN - SE PRETENDE REVOCAR ACTA DE ENTREGA, EXISTE ACCION POPULAR Y NULIDAD DE ACTO ADMINISTRATIVO DE CATASTRO PENDIENTE POR RESOLVER PARA QUE CONTINUE EL TRAMITE PROCESAL. | AD10: CON FALLO | AE10: N/A | AF10: EN EJECUCIÓN - DADEP INTERVENCIÓN DEFENSA BIENES DEL DISTRITO CON OTRAS ACCIONES CONSTITUCIONALES Y JUDICIALES.
A11: 709676 | B11: CIVIL | C11: 1998-00939 | D11: PERTENENCIA | E11: 37231 | F11: JUZGADO 40 - CIVIL DEL CIRCUITO | G11: JAMMER SAUL HERNANDEZ | H11: MARIA EUGENIA MARTÍNEZ, HENRY GOMEZ RAMOS, ROSA HELENA GONZÁLEZ CUELLAR Y OTROS. | I11: PERSONAS INDETERMINADAS | J11: DIRECTA | K11: INTERVINIENTE | L11: PROCESO DE PERTENENCIA SOBRE UN PREDIO FISCAL | M11: NA | N11: NULIDAD DE LA SENTENCIA DE PERTENENCIA DE FECHA 26 DE MARZO DE 2004 | O11: NA | P11: NA | Q11: NA | R11: BIEN FISCAL | S11: 2-1250 | T11: SANTA FE | U11: 240,4 | V11: NA | W11: NA | X11: NA | Y11: NA | Z11: 26/03/2004 | AA11: NA | AB11: NA | AC11: SE PRESENTA NULIDAD DE LA SENTENCIA LA CUAL ES NEGADA EN PRIMERA Y SEGUNDA INSTANCIA | AD11: CON FALLO | AE11: SGC | AF11: CON PRONUNCIAMIENTO EN SEGUNDA INSTANCIA NEGANDO LA SOLICITUD DE NULIDAD, PROCESO ARCHIVADO, SIN ACTUACIONES PENDIENTES.
A12: 588924 | B12: CIVIL | C12: 2001-00056 | D12: EJECUTIVO | E12: 36922 | F12: JUZGADO 5 CIVIL DEL CIRCUITO DE EJECUCIÓN DE BOGOTÁ | G12: JAMMER SAUL HERNANDEZ | H12: BANCO DE BOGOTÁ S.A. | I12: LUIS EDUARDO MOSQUERA-COOPERATIVA DEL VIVIENDA DEL MAGISTERIO | J12: DIRECTA | K12: INTERVINIENTE | L12: PROCESO EJECUTIVO ENTRE PARTICULARES EN DONDE SE ORDENÓ EL EMBARGO DE LAS ZONA DE CESIÓN DE LA URABNIZACIÓN COOVIMAC LTDA | M12: N/A | N12: SE PRETENDE LEVANTAR LA MEDIDA DE EMBARGO QUE PESA SOBRE EL INMUEBLE 50C-233951 | O12: URBANIZACIÓN MULTIFAMILIAR COOVIMAC LTDA | P12: N/A | Q12: N/A | R12: ZONA DE CESIÓN | S12: 1519-1, 1519-2, 1519-3 | T12: ENGATIVA | U12: 1937,37 MTS2 | V12: N/A | W12: N/A | X12: N/A | Y12: N/A | Z12: 37369 | AA12: 37547 | AB12: N/A | AC12: EN FECHA 29 DE MARZO DE 2023, SE PROCEDE A ORDENAR LA TERMINACIÓN POR DESISTIMIENTO TÁCITO DEL PROCESO | AD12: CON FALLO | AE12: N/A | AF12: CON SENTENCIA DE PRIMERA Y SEGUNDA INSTANCIA EJECUTORIADAS EN EJECUCIÓN. CON SOLICITUD PARA CANCELAR LAS MEDIDAS CAUTELARES IMPUESTAS. SE ORDENA CANCELAR LA MEDIDA DE EMBARGO QUE PESABA SOBRE EL INMUEBLE Y SE INFORMA A LA SRI. SIN ACTUACIONES PENDIENTES.
A13: 597584 | B13: CIVIL | C13: 2019-00307 11001310300420190030700 | D13: NULIDAD DE ESCRITURA PÚBLICA | E13: 43452 | F13: JUZGADO 4 CIVIL DEL CIRCUITO DE BOGOTÁ | G13: GENARO SALAZAR GONZALEZ | H13: DADEP | I13: JOSE PABLO EMILIO YOPASA MUÑOZ | J13: DIRECTA | K13: DEMANDADO | L13: NULIDAD DE ESCRITURA PÚBLICA - DONACIÓN | M13: N/A | N13: NULIDAD DE EP POR OBJETO ILÍCITO | O13: JAVA II SECTOR | P13: N/A | Q13: N/A | R13: ZONA DE CESIÓN | S13: 1878 | T13: SUBA | U13: 19755 | V13: N/A | W13: N/A | X13: N/A | Y13: N/A | Z13: N/A | AA13: N/A | AB13: N/A | AC13: NOTIFICACIONES DE LOS DEMANDADOS HEREDEROS Y JAC BARRIO JAVA II SECTOR | AD13: EN CURSO | AE13: N/A | AF13: EL JUZGADO REQUIERE A LA PARTE DEMANDANTE PARA INFORMAR NOTIFICACION 26-09-2024
A14: 164016 | B14: CONTENCIOSO ADMINISTRATIVA | C14: 2005-01924 | D14: EJECUTIVO | E14: 38580 | F14: JUZGADO 58 ADMINISTRATIVO DEL CIRCUITO DE BOGOTÁ | G14: JAMMER SAUL HERNANDEZ | H14: DADEP | I14: FABIO ZAMORA CONTRERAS | J14: DIRECTA | K14: DEMANDADO | L14: INCUMPLIMIENTO CONTRATO ARRENDAMIENTO 004-1993 | M14: NA | N14: INCUMPLIMIENTO CONTRATO ARRENDAMIENTO 004-1993 | O14: NA | P14: 24676716 | Q14: NA | R14: BIEN DE USO PUBLICO | S14: NA | T14: TEUSAQUILLO | U14: NA | V14: NA | W14: NA | X14: NA | Y14: NA | Z14: 40855 | AA14: NA | AB14: NA | AC14: SEGUIMIENTO SECRETARÍA JURÍDICA - PROCESO DE REPRESENTACIÓN INDIRECTA | AD14: EN CURSO | AE14: N/A | AF14: ACREDITA TRAMITE EMBARGO DE CUENTAS - SEGUIMIENTO A BIENES EN CABEZA DEL DEMANDADO PARA INFORMAR AL DESPACHO
A15: 705577 | B15: PENAL | C15: 2022-69826 | D15: PENAL | E15: 44807 | F15: FISCALÍA 212 ADMÓN PÚBLICA | G15: JOSE AGUSTÍN AVENDAÑO | H15: DADEP | I15: FORJA S.A. | J15: DIRECTA | K15: DENUNCIANTE | L15: FORJA | M15: ENRIQUECIMIENTO ILÍCITO DE PARTICULARES - USURPACIÓN DE FUNCIONES | N15: A RAIZ DE LA TERMINACIÓN DE UN CONTRATO CAMEP ENTRE FORJA Y EL DADEP, EL PRIMERO NO RESTITUYÓ EL BIEN Y GENERÓ FRUTOS SOBRE EL MISMO, CONSERVANDO EL BIEN PÚBLICO PESE A LOS DIVERSAS SOLICITUDES DE RESTITUCIÓN Y ACCIONES JURÍDICAS POR PARTE DEL DADEP | O15: CHICO NORTE - NUEVA URBANIZACIÓN SANTA BARBARA II SECTOR II ETAPA CENTRO COMERCIAL | P15: N/A | Q15: N/A | R15: N/A | S15: 2545 | T15: USAQUEN | U15: N/A | V15: N/A | W15: N/A | X15: N/A | Y15: N/A | Z15: N/A | AA15: N/A | AB15: N/A | AC15: Transcurrido el mes que el despacho menciono, se asiste al mismo el dia 14/05/24 donde el fiscal indica que se encuentra en estudio el caso e indica volver dentro del mes siguiente. | AD15: EN CURSO | AE15: N/A | AF15: INDAGACIÓN
A16: 163864 | B16: CONTENCIOSO ADMINISTRATIVA | C16: 2005-01928 | D16: EJECUTIVO | E16: 38502 | F16: TRIBUNAL CONTENCIOSO ADMINISTRATIVO DE CUNDINAMARCA - SECCIÓN TERCERA | G16: MARIA FERNANDA CRUZ | H16: DADEP | I16: LUZ MARINA ARROYAVE DE RAMIREZ | J16: DIRECTA | K16: DEMANDADO | L16: INCUMPLIMIENTO CONTRATO ARRENDAMIENTO 0011-1993 | M16: NA | N16: INCUMPLIMIENTO CONTRATO ARRENDAMIENTO 0011-1993 | O16: NA | P16: 26976535 | Q16: NA | R16: BIEN FISCAL | S16: 2-440 | T16: SANTAFE | U16: NA | V16: NA | W16: NA | X16: NA | Y16: NA | Z16: 38827 | AA16: NA | AB16: NA | AC16: INFORMAR QUE BIENES SE ENCUENTRAN EN CABEZA DE LA DEMANDADA. A LA FECHA NO ME HAN RECONCIDO PERSONERÍA JURÍDICA | AD16: CON FALLO | AE16: N/A | AF16: SENTENCIA Y SE ESTA TRAMITANDO DE OBTENCION DEL DINERO ADEUDADO CON MEDIDAS CAUTALES
A17: 563426 | B17: CONSTITUCIONAL | C17: 2017-00693 | D17: ACCION POPULAR | E17: 43039 | F17: JUZGADO 13 CIVIL DEL CIRCUITO | G17: MAGDA BOLENA ROJAS BALLESTEROS | H17: DADEP | I17: INVERSIONES ALCABAMA S.A., INVERSIONES DIPRECA S.A. | J17: DIRECTA | K17: DEMANDADO | L17: ENTREGA DE ZONAS CE CESIÓN | M17: NA | N17: ENTREGUE, FORMAL Y MATERIALMENTE, ESCRITURE Y DOTE LAS ZONAS DE CESION NGRATUITAS A FAVOR DEL DISTRITO CAPITAL DE LA URBANIZACIÓN CAMINO VERDE | O17: LAS FLORES | P17: N/A | Q17: N/A | R17: ZONA DE CESIÓN | S17: 3167-3168 | T17: SUBA | V17: N/A | W17: N/A | X17: N/A | Y17: N/A | Z17: N/A | AA17: N/A | AB17: N/A | AC17: 2022-06-21 Se fija fecha para la celebración de audiencia de pacto para el 17 de agosto de 2022 a las 10:00AM 2022-08-17 Previo al inicio de la audiencia: 1. Se desiste de la solicitud de vinculación de máximo Beltrán RodrÍguez 2. Se desiste de la solicitud de desvinculación de Luis Hernán Noguera Garzón. 3. El juez resuelve aplazar la audiecia debido a la inasistencia de Luis Hernán Noguera Garzón y en atención al avance en el cumpimiento de la sociedad Alcabama S.A., quienes afirman haber suspendido el avance con ocasión de un oficio enviado por SRI por el cual la UAESP manifestó no darle continuidad al trámite. 4. Se acordó aclararle a la UAESP que podían continuar con el trámite y adelantar una mesa de trabajo con los urbanizadores para conocer los avances. 2022-09-16 Se adelanta mesa de trabajo con INVERSIONES ALCABAMA S.A., IDU, UAESP, IDRD y el JBJCM para conocer los avances. En desarrollo de la reunión se aclaró la inexistencia de impedimento alguno que obstaculizara continuar con el trámite de entrega ante la UAESP. 2022-09-28 Se envía oficio a la UAESP acalarando la inexistencia de impedimento alguno que obstaculizara continuar con el trámite de entrega ante la UAESP.2023-07-06 pendiente de aceptación de poder. 25/08/23. Se notificó por estado auto que ordenó requerir a la parte actora 3. El juez resuelve aplazar la audiecia debido a la inasistencia de Luis Hernán Noguera Garzón y en atención al avance en el cumpimiento de la sociedad Alcabama S.A., quienes afirman haber suspendido el avance con ocasión de un oficio enviado por SRI por el cual la UAESP manifestó no darle continuidad al trámite. 4. Se acordó aclararle a la UAESP que podían continuar con el trámite y adelantar una mesa de trabajo con los urbanizadores para conocer los avances. 2022-09-16 Se adelanta mesa de trabajo con INVERSIONES ALCABAMA S.A., IDU, UAESP, IDRD y el JBJCM para conocer los avances. En desarrollo de la reunión se aclaró la inexistencia de impedimento alguno que obstaculizara continuar con el trámite de entrega ante la UAESP. 2022-09-28 Se envía oficio a la UAESP acalarando la inexistencia de impedimento alguno que obstaculizara continuar con el trámite de entrega ante la UAESP. 2023-07-06 pendiente de aceptación de poder. 25/08/23. Se notificó por estado auto que requirió al DADEP para allegar comprobantes de notificación de la vinculación a la AP de la UAESP. 28/08/23. Se remite al despacho cumplimiento de la orden del auto del 25 de agosto de 2023. 12/09/2023. Contestación de la demanda. 25/10/2023. Traslado contestación de la demanda por el término de 5 días. 14/11/2023. Al Despacho. 31/01/2024. Se notificó por estado auto que citó a audiencia de pacto para el 13/03/24 a las 02:00 pm. 08/02/24. Con memorando 20241300012213 se solicitó a la SRI información sobre el estado actual de las zonas de cesión para efectos de la audiencia de pacto de cumplimiento (pendiente respuesta - fecha límite 26 de febrero de 2024). 14/02/2024. Memorando 20242010012973 de la SRI informando el estado actual de las áreas de cesión. 28/02/2024. Se radicó solicitud de nulidad. 29/02/2024. Al Despacho solicitud de nulidad. Pendiente de pronunciamiento despacho.04-08-2024 interposición de recurso contra auto que rechaza nulidad interpuesto por ENEL. fija diligencia de paxcto para el 23 de julio de 2024 auto de fecha 19 marzo de 2024. auto de fecha 12 abril de 2024 Traslado Art. 326 Inciso 1° C.G.P.. 29/04/2024. Se notificó por estado auto que resolvió negar el recurso de apelación. 23/07/2024. Se asistió a la audiencia de pacto la cual fue reprogramada para el 29/07/24 a las 09:00 am, teniendo en cuenta los inconvenientes del juez para conectarse a la misma. 29/07/2024. Se llevó a cabo la audiencia de pacto, no obstante la misma fue suspendida con el fin de otorgar tiempo suficiente a las partes para que lleguen a un acuerdo teniendo en cuenta los avances en el trámite de la cesión de zonas comunes, por lo que la audiencia se reprogramó para el 4 de febrero a las 09:00 am. 29/07/2024. Con memorando 20241300037153 se solicitó a la SRI especial seguimiento al caso atendiendo a la solicitud del Juez de gestionar el asunto de entrega de cesión de zonas comunes. 28/11/24. Se notificó por estado auto que aceptó renuncia a poder audiencia de pacto de cumplimiento el 4 de febrero de 2025 a las 9 am sin embargo teniendo en cuenta que se programo una mesa de soluciones para el 17 de febrero de 2025 para solventar el tema de ENEL CODENSA, el juzgado suspende la diligencia y solicita se informe inmediatamente por ultima vez los resultados de la mesa de soluciones con las entidades | AD17: EN CURSO | AE17: SRI | AF17: PARA AUDIENCIA DE PACTO DE CUMPLIMIENTO
A18: 526574 | B18: CONSTITUCIONAL | C18: 2015-00516 | D18: ACCION POPULAR | E18: 42262 | F18: JUZGADO 2 CIVIL DEL CIRCUITO DE ORALIDAD DE BOGOTÁ | G18: MARIA FERNANDA MADIEDO SANCHEZ | H18: DADEP | I18: FIDUCIARIA DE OCCIDENTE - BIENES Y COMERCIO - SADINSA | J18: DIRECTA | K18: DEMANDADO | L18: ENTREGA ZONAS DE CESIÓN | M18: NA | N18: ENTREGA Y ESCRITURACION ZONAS DE CESION VILLA ALSACIA | O18: VILLA ALSACIA LOTE 1 SECTOR A | P18: NA | Q18: NA | R18: ZONA DE CESIÓN | S18: 3205 | T18: KENNEDY | U18: 145038.7 | V18: NA | W18: NA | X18: NA | Y18: NA | Z18: NA | AA18: NA | AB18: NA | AC18: SEGUIMIENTO PROCESAL - NOTIFICADO CURADOR ADLITEM QUIEN CONTESTÓ DEMANDA Y ENTRÓ AL DESPACHO - A LA ESPERA TRASLADO EXCEPCIONES. AUDIENCIA PACTO DE CUMPLIIMIENTO PARA EL 1 DE OCTUBRE DE 2019. AL DESPACHO PARA RESOLVER RECURSO DE REPOSICION 9-2-2024 EN SECRETARIA CON EL AUTO DEL 12 DE MARZO DE 2020 QUE PONE EN CONOCIMIENTO DE CONFORMIDAD CON LA SOLICITUD DE ACLARACION ELEVADA POR EL APODERADO DE LA PARTE ACTORA, TENGASE PARA TODOS LOS EFECTOS POR NO ESCRITO EL ACAPITE DICTAMEN PERICIAL POR NO HABERSE SOLICITADO CON LA ACCION POPULAR. POR SECRETARIA DESE CUMPLIMIENTO AL AUTO QUE DECRETO PRUEBAS. A LA FECHA 10/05/2022 NO SE EVIDENCIA NINGUN ESTADO DIFERENTE AL DE PRUEBAS, POR LO CUAL SE REALIZARA EL RESPECTIVO //SEGUIMIENTO AL PROCESO. se consulta el proceso en la web de la rama el 9 de agosto de 2022 y se encuentra al despacho desde el 26 Marzo de 2021. se llevo a cabo mesa de trabajo el dia 6 de julio de 2022 con SRI y el accionante. Sin embargo, se manifiesto que no se va hacer modificacion de las zonas de cesion que en su tiempo presuntamente el DADEP no quiso entregar, se atienen a las resultas del proceso. se remite poder el 20-10-2022 para revision y posterior envio al despacho a fin de dar impulso procesal. El dia 24-10-2022 se radica 20221100165361 poder por correo electronico se reirera solicitud al despacho ya que no se registra la informacion en la web de la rama. se realiza consulta en la rama el 19-01-2023 ingresa al despacho con poder dadep. Auto de fecha 8-3-2023 requiere al accionado para que se pronuncie sobre el dictamen decretado a su solicitud. SE radica el 5-9-2023 solicitud de impulso procesal ya que el accionado no allega la prueba decretada. El 21-11-2023 se allega dictamen aportado por la demandada.El 27-12-2023 se solicito actualizacion estudio tecnico juridico. el 13-12-2023 se interpone recurso de reposicion contra auti de fecha 6-12-2023. a la espera de las resultas del recurso. Mediante oficio orfeo 20241300011381 de fecha 1 -2-2023 se remite estudio tecnico juridico actualizado del predio al juzgado para los fines que estime pertinentes.auto de fecha 9-10-2024 revoca parcialmente auto corre traslado a las partes sobre el estudio tecnico actualizado allegado por el DADEP a las partes.16/10/2024 APODERADA FIDUCIARIA DE OCCIDENTE S.A. / RECURSO DE REPOSICIÓN Y EN SUBSIDIO DE APELACIÓN. 28-10 -2024 Traslado Recurso Reposición Art. 319 C.G.P. al Despacho desde el 2024-11-05. una vez se resuelva recurso radicar informe tecnico. | AD18: EN CURSO | AE18: SRI | AF18: PRUEBAS
A19: 255193 | B19: CONTENCIOSO ADMINISTRATIVA | C19: 2006-00027 11001333103820060002700 | D19: EJECUTIVO | E19: 38985 | F19: JUZGADO 59 ADMINISTRATIVO | G19: GENARO SALAZAR GONZALEZ | H19: DADEP | I19: FRANCISCO JAVIER GOMEZ RAMIREZ | J19: DIRECTA | K19: DEMANDADO | L19: INCUMPLIMIENTO CONTRATO ARRENDAMIENTO 0051-1993 | M19: NA | N19: INCUMPLIMIENTO CONTRATO ARRENDAMIENTO 0051-1993 | O19: NA | P19: 75357472 | Q19: NA | R19: BIEN FISCAL | S19: 2-440 | T19: SANTAFE | U19: NA | V19: NA | W19: NA | X19: NA | Y19: NA | Z19: 40305 | AA19: NA | AB19: NA | AC19: AUTO REQUIERE AL SECUESTRE 22-11-2022, EL VEHICULO EMBARGADO NO APARECE FISICAMENTE, ES UN MODELO BASTANTE ANTIGUO LO QUE VALE ES EL CUPO (TAXI) DE NO APARECER SE DEBE BUSCAR EL DESISTIMIENTO TACITO Y ARCHIVAR. | AD19: CON FALLO | AE19: N/A | AF19: AUTO REQUIERE A LOS DDOS 30-07-2024
A20: 617610 | B20: CONSTITUCIONAL | C20: 2019-00611 11001310303520190061100 | D20: ACCION POPULAR | E20: 43776 | F20: JUZGADO 35 CIVIL DEL CIRCUITO DE BOGOTÁ | G20: MAGDA BOLENA ROJAS BALLESTEROS | H20: DADEP | I20: INVERSION Y DESARROLLO BARRANCO | J20: DIRECTA | K20: DEMANDADO | L20: ENTREGA DE ZONAS CE CESIÓN | M20: N/A | N20: CONSTRUCTORA INCUMPLIO CON LA OBLIGACION DE ESCRITURAR Y ENTREGAR LAS ZONAS DE CESIÓN. | O20: PANTANOS | P20: N/A | Q20: N/A | R20: ZONA DE CESIÓN | S20: 3616 | T20: KENNEDY | U20: 8305 | V20: NO APLICA | W20: N/A | X20: N/A | Y20: N/A | Z20: N/A | AA20: N/A | AB20: N/A | AC20: ESTA AL DESPACHO PARA SEÑALAR FECHA DE PACTO DE CUMPLIMIENTO 11-07-2023. Se notificó por estado auto que fijó fecha para audiencia de pacto el 21/02/2025 a las 09:00 am | AD20: EN CURSO | AE20: N/A | AF20: EL JUZGADO DECIDE EL RECURSO 18-04-2024
A21: 574069 | B21: CONSTITUCIONAL | C21: 2018-00106 | D21: ACCION POPULAR | E21: 43083 | F21: JUZGADO 2 CIVIL DEL CIRCUITO | G21: SHIRLEY AVELLANEDA PEÑA | H21: DADEP | I21: KADAS | J21: DIRECTA | K21: DEMANDADO | L21: SORATAMA | M21: N/A | N21: ENTREGA Y ESCRITURACION ZONAS DE CESION URBANIZACION BOSQUES DE SORATAMA | O21: BOSQUES DE SORAMATA | P21: N/A | Q21: N/A | R21: ZONA DE CESIÓN | S21: 3626 | T21: USAQUEN | U21: 33938.2 | V21: N/A | W21: N/A | X21: N/A | Y21: N/A | Z21: N/A | AA21: N/A | AB21: N/A | AC21: SEGUIMIENTO PROCESAL: CONTESTACIÓN DEMANDA Y ACTUACIONES PROCESALES. MEDIANTE RADICADO 20211100131541 MEMORIAL SOLICITANDO AL DESPACHO VINCULAR AL LIQUIDADOR. DIFERENTES MESAS DE TRABAJO CON EL LIQUIDADOR Y LA SRI. 27-04-2022 PODER IDRD. 25-07-2022 LA SRI ESTA GESTIONANDO ACTA DE TOMA DE POSESIÓN DE ACUERDO CON LA MESA DE TRABAJO CELEBRADA ENTRE LA OAJ Y SRI. AUTO DEL 2 DE NOVIEMBRE DE 2022, FIJA FECHA DE PACTO DE CUMPLIMIENTO PARA EL 24 DE NOVIEMBRE DE 2022 A LAS 10:00 A.M. AUTO 30/05/2023 FIJA AUDIENCVIA PACTO DE CUMPLIMIENTO 22/06/2023 A LAS 10:00 A.M. SE SUSPENDE DILIGENCIA DE PACTO DE CUMPLIMIENTO PARA EL 05-11-2023. MEDIANTE MEMORANDO ORFEO 2023130038133 SE SOLICITO A SRI INFORMACION DEL ESTADO DEL TRAMITE DE ESCRITURACI{ON. ORFEO 20232030039163 SE INFORMO ESTADO DE AVANCE DE LA ESCRITURACIÓN. RADICADO ORFEO 20231300166801 DEL 31-10-2023 SE SOLICITO AL DESPACHO FIJAR FECHA DE AUDIENCIA DE PACTO SUSPENDIDA. AL DESPACHO SIN ACTUACIÓN.22-01-2024 AL DESPACHO. | AD21: EN CURSO | AE21: SRI | AF21: FIJACION AUDIENCIA DE PACTO DE CUMPLIMIENTO
A22: 255007 | B22: CONTENCIOSO ADMINISTRATIVA | C22: 2006-00063 11001333103320060006300 | D22: EJECUTIVO | E22: 39028 | F22: JUZGADO 65 - ADMINISTRATIVO SECCIÓN TERCERA | G22: GENARO SALAZAR GONZALEZ | H22: DADEP | I22: DORIS ROCIO VANEGAS OLGUIN | J22: DIRECTA | K22: DEMANDADO | L22: INCUMPLIMIENTO CONTRATO ARRENDAMIENTO 0016-1999 | M22: NA | N22: INCUMPLIMIENTO CONTRATO ARRENDAMIENTO 0016-1999 | O22: NA | P22: 26979466 | Q22: NA | R22: BIEN FISCAL | S22: 2-440 | T22: SANTAFE | U22: NA | V22: NA | W22: NA | X22: NA | Y22: NA | Z22: 40622 | AA22: NA | AB22: NA | AC22: PROCESO CON SENTENCIA DEL EJECUTIVO, SE ENCUENTRA EMBARGADO LA CUOTA DE UN INMUEBLE DE DORIS ROCIO VANEGAS HOLGUIN | AD22: CON FALLO | AE22: N/A | AF22: SECUESTRO DEL BIEN INMUEBLE DECRETADO EL 23 DE MARZO DEL 2022, NO SE HA PODIDO CONCRETAR POR FALTA DE UBICACIÓN DEL PREDIO ESTA EN LA ALCALDIA DE BOSA.
A23: 681651 | B23: CIVIL | C23: (2007-00240) (11001310300220070024000) | D23: PERTENENCIA | E23: 39135 | F23: JUZGADO 47 CIVIL DEL CIRCUITO DE BOGOTÁ D.C. | G23: GENARO SALAZAR GONZALEZ | H23: ANA DOLORES SARMIENTO Y 2OTROS | I23: JOSE HECTOR BERMNUDEZ VARGAS Y OTROS | J23: DIRECTA | K23: INTERVINIENTE | L23: PERTENENCIA | M23: NO APLICA | N23: TERCEROS SE APODERARON DE UNA ZONA DE CESION EN EL TRAMITE JUDICIAL DE PERTENENCIA | O23: VILLAS DEL DORADO | P23: N/A | Q23: N/A | R23: ZONA DE CESIÓN | S23: 3103-7 | T23: ENGATIVA | U23: 875.80 MTS2 | V23: N/A | W23: N/A | X23: N/A | Y23: N/A | Z23: 40158 | AA23: N/A | AB23: N/A | AC23: SE PRESENTO INCIDENTE DE NULIDAD PROCESAL POR LA AFECTACIÓN DE UN PREDIO DESTINADO AL USO PUBLICO, EL JUZGADO CORRIO TRASLADO DEL MISMO. | AD23: CON FALLO | AE23: N/A | AF23: DESPACHO 26-09-2024 PARA TENER POR NOTIFICADO Y CONTESTADA LA DEMANDA Y DECRETAR PRUEBAS
A24: 606071 | B24: CONSTITUCIONAL | C24: 2019-00473 | D24: ACCION POPULAR | E24: 43664 | F24: JUZGADO 21 CIVIL DEL CIRCUITO DE BOGOTÁ | G24: MARIA FERNANDA MADIEDO SANCHEZ | H24: DADEP | I24: CONTRUCTORA LAS GALIAS S.A. | J24: DIRECTA | K24: DEMANDADO | L24: ENTREGA ZONAS DE CESIÓN | M24: N/A | N24: ZONAS DE CESION URBANIZACION QUINTAS DE CASTILLA | O24: QUINTAS DE CASTILLA | P24: N/A | Q24: N/A | R24: ZONA DE CESIÓN | S24: 848-1 AL 848-10 | T24: KENNEDY | U24: 6.196.65 | V24: N/A | W24: N/A | X24: N/A | Y24: N/A | Z24: N/A | AA24: N/A | AB24: N/A | AC24: Audiencia de pacto de cumplimiento llevada a cabo el día 06 de abril de 2022, donde la apoderada judicial de la parte accionada manifiesta que la certificación emitida por la UAESP, se les refundió, por tal motivo no la han podido aportar y completar todos los documentos para seguir con el trámite correspondiente; se envía petición a la UAESP de la respectiva acta por parte del juzgado y del DADEP con Rad No. 20221100051721, la audiencia se suspende y continúa el 08 de junio de 2022 la cual se declara fallida, ingresa el proceso al despacho para decretar las pruebas a que haya lugar, mediante auto de pruebas de 26 de septiembre de 2022, se decretan como pruebas solicitadas por la sociedad constructora, se señala interrogatorio de parte del representante del DADEP, el día 23 de enero de 2023 a las 2:15 pm, se decreta los testimonios de los señores, Ricardo Sánchez, Fabian Leonardo Gutiérrez Leal, María Cristina Naranjo y Carlos Humberto Guzmán, el día 30 de enero de 2023, Prueba de oficio: Se decreta el interrogatorio de parte del representante legal o quien haga sus veces de la sociedad demandada, el día 23 de enero a las 04:00 pm. se requiere la elaboración de dictamen pericial y para su presentación conceden el termino de 20 días, se procede a hacer la solicitud a la SRI, mediante memorando con Radicado DADEP No. 20221100068823, el cual se remite al juzgado el día 24 de octubre de 2022 con Radicado DADEP No. 20221100167141. Se asiste a audiencia el dia 23 de Enero de 2023, para pruebas en la misma se solicita por parte del apoderado del demandado la suspension y se coadyuva la solicitud por parte del DADEP se suspende la audiencia hasta el 28 de abril de 2023 a las 10 am. el despacho dio un termino de 5 dias para que el accionado remitiera cuestionario por parte de las galias. Audiencia de fecha 28 de Abril se suspende por 2 meses, toda vez que ya se esta en la etapa de escrituracion de las zonas de cesion. se solicita el dia 29 de Mayo de 2023 a SRI informe sobre el trámite de escrituración a fin de informar al despacho. se coadyuva solicitud de suspension de la diligencia programada para el 28 junio de 2023 para terminar los tramites administrativos, pendiente se radique por parte del urbanizador o notaria 15 la escritura publica para firma de la Directora. audiencia de continuacion 14-9-2023 a las 2:30 pm. se asiste a dligencia se presentan escrituras con transferencia zonas de cesion ingresa al despacho 25-9-2023 para sentencia. el 15 -3-2024 se profiere sentencia que aprueba el pacto de cumplimiento al haberse cumplido con la transferencia de las zonas de cesion. archivar proceso fecha 3 abril de 2024. | AD24: CON FALLO | AE24: SRI | AF24: ARCHIVO
A25: 164172 | B25: CONTENCIOSO ADMINISTRATIVA | C25: 2005-01927 | D25: EJECUTIVO | E25: 38580 | F25: JUZGADO 61 - ADMINISTRATIVO SECCIÓN TERCERA | G25: JAMMER SAUL HERNANDEZ | H25: DADEP | I25: EDDY ROCIO MELO CARRANZA | J25: DIRECTA | K25: DEMANDADO | L25: INCUMPLIMIENTO CONTRATO ARRENDAMIENTO 0010-1994 | M25: NA | N25: INCUMPLIMIENTO CONTRATO ARRENDAMIENTO 0010-1994 | O25: NA | P25: 51941169 | Q25: NA | R25: BIEN FISCAL | S25: 2-440 | T25: SANTAFE | U25: NA | V25: NA | W25: NA | X25: NA | Y25: NA | Z25: 40415 | AA25: NA | AB25: NA | AC25: SEGUIMIENTO SECRETARÍA JURÍDICA - PROCESO DE REPRESENTACIÓN INDIRECTA | AD25: EN CURSO | AE25: N/A | AF25: PENDIENTEGESTIÓN EMBARGO DE CUENTAS - SEGUIMIENTO A BIENES EN CABEZA DEL DEMANDADO PARA INFORMAR AL DESPACHO
A26: 617584 | B26: CONSTITUCIONAL | C26: 2019-00730 11001310302220190073000 | D26: ACCION POPULAR | E26: 43664 | F26: JUZGADO 22 CIVIL DEL CIRCUITO DE BOGOTÁ | G26: MAGDA BOLENA ROJAS BALLESTEROS | H26: DADEP | I26: FIDUCIARIA DE OCCIDENTE | J26: DIRECTA | K26: DEMANDADO | L26: ENTREGA DE ZONAS CE CESIÓN | M26: N/A | N26: CONSTRUCTORA INCUMPLIO CON LA OBLIGACION DE ESCRITURAR Y ENTREGAR LAS ZONAS DE CESIÓN. | O26: TINGUA | P26: N/A | Q26: N/A | R26: ZONA DE CESIÓN | S26: 3892 | T26: BOSA | U26: 14900 | V26: N/A | W26: N/A | X26: N/A | Y26: N/A | Z26: N/A | AA26: N/A | AB26: N/A | AC26: EL DESPACHO NO REPUSO AUTO Y ORDENO VINJCULAR A COLSUBSIDIO Y CURADOR URBANO 3. 16/02/2024. Se notificó por estado auto que requirió al DADEP para que remita cumplimiento del auto so pena de desistimiento de la demanda. 27/02/2024. Cumplimiento del auto por parte del DADEP. 04/10/2024. Se notificó por estado auto que ordenó vincular a la Secretaría Distrital del Hábitat. 23/10/2024. Memorial de cumplimiento del auto del 3 de octubre de 2024 por parte del DADEP a través del cual se remitió constancia de notificación a la Secretaría Distrital del Hábitat. 12/11/2024. Contestación demanda Secretaría de Hábitat | AD26: EN CURSO | AE26: N/A | AF26: DESPACHO 23-04-2024 PARA SEÑALAR FECHA DE PACTO DE CUMPLIMIENTO
A27: 391844 | B27: CONSTITUCIONAL | C27: 2012-00546 | D27: ACCION POPULAR | E27: 41151 | F27: JUZGADO 21 CIVIL DEL CIRCUITO DE BOGOTÁ | G27: SHIRLEY AVELLANEDA PEÑA | H27: DADEP | I27: CONSTRUCTORA NORMANDIA | J27: DIRECTA | K27: DEMANDADO | L27: ENTREGA Y ESCRITURACION BOSQUES DE SALAMANCA | M27: NA | N27: ENTREGA Y ESCRITURACION BOSQUES DE SALAMANCA | O27: BOSQUES DE SALAMANCA | P27: NA | Q27: NA | R27: ZONA DE CESIÓN | S27: 3977 | T27: SUBA | U27: 3065 | V27: NA | W27: NA | X27: NA | Y27: NA | Z27: NA | AA27: NA | AB27: NA | AC27: SEGUIMIENTO PROCESAL - SE ADELANTA GESTIONES TENDIENTES A ENTREGA ZONAS CESIÓN DE MANERA DIRECTA CON URBANIZADOR - PENDIENTE ESCRITURACIÓN. RADICARON SOLICITUD DEL 545 PERO AL PARECER SRI DETERMINA QUE NO ES VIABLE, SE CONTINUA CON PROCESO JUDICIAL. Se decretan pruebas y se señala para practicarlas 19/04/2024 10 A.M.26-01-2024 NO SE TIENE EN CUENTA CONTESTACION DE IDRD. SE CONVOCA PARA AUDIENCIA DE PACTO DE CUMPLIMEINTO EL DIA 9 DE DICIEMBRE DE 2019 A LAS 2:30 PM. 26-09-2022 FIJACION ESTADO AUTO RECONOCE PERSONERIA Y CONTESTACION DEMANDA Y CONCEDE TERMINO PARA APORTAR CERTIFICADO DE TRADICION ACTUALIZADO DEL BIEN OBJETO DE ACCION. 24-10-2023 AUTO DE PRUEBAS FIJA FECHA DE AUDIENCIA DE TESTIMONIOS ABRIL 13 DE 2024. EN DILIGENCIA LLEVADA A CABO EL 24 DE FEBRERO, LA JUEZA ORDENO HACER UN LEVANTAMIENTO TOPORAFICO, ESTUDIO DE TÍTULOS Y VISITA PARA PODER TENER CLARA LA FÓRMULA DE PACTO. POR LO ANTERIOR, SE SUSPENDE LA DILIGENCIA PARA QUE EL DADEP REALICE ESTOS ESTUDIOS. MEDIANTE OFICIO 20211100113181 01/10/2021 SE ALLEGARON AL DESPACHO ESTUDIO DE TITULOS Y LEVANTAMIENTO TOPOGRAFICO. 2022-05-27 REQUERIMIENTO JUZGADO PARTE ACTORA ALLEGAR OFICIOS A JARDIN BOTANICO, IDRD, SDP. 22-06-2022 MEDIANTE ORFEO 20221100089111 SE REMITIERON LOS OFICIOS SOLICITADOS POR EL DESPACHO. AL DESPACHO CON DILIGENCIAMIENTO OFICIO PARTE ACTORA Y PODER DE LA UAESP. 26-09-2022: AUTO RECONOCE PERSONERIA Y CONTESTACION DEMANDA JARDIN BOTANICO Y SOLICITUD DE CERTIFICADOS DE TRADICIÒN Y LIBERTAD. 19-10-2022 REMISION DE CERTIFICADOS DE TRADICION Y LIBERTAD. 27-02-2023 AUTO FIJA AUDIENCIA DE PACTO DE CUMPLIMIENTO. 28-07-2023 SE LLEVO A CABO AUDIENCIA DE PACTO DE CUMPLIMIENTO. AUDIENCIA DE PRUEBAS 19-04-2024. AUTO ALEGATOS DE CONCLUSION 05-06-2024. 12-06-2024 PRESENTACION ALEGATOS DE CONCLUSION. 18-12-2024 SENTENCIA DESFAVORABLE.14-01-2025 PRESENTACION RECURSO DE APELACIÓN. | AD27: EN CURSO | AE27: SRI | AF27: SENTENCIA DE PRIMERA INSTANCIA
A28: 764789 | B28: CIVIL | C28: (2023-00357) 11001310301320230035700 | D28: NULIDAD DE ESCRITURA PÚBLICA | E28: 45243 | F28: JUZGADO 13 CIVIL DEL CIRCUITO | G28: GENARO SALAZAR GONZALEZ | H28: DADEP | I28: NAMASTE S.A. | J28: DIRECTA | K28: DEMANDADO | L28: NULIDAD DE ESCRITURA PUBICA | M28: N/A | N28: El representante legal de la Asociación Provivienda de Trabajadores en su calidad de urbanizador responsable de hacer entrega de las zonas de cesión al Distrito Capital, incumplió con sus obligaciones urbanísticas señaladas en la mencionada Resolución 085 que aprobó los planos urbanísticos B16/4-18 al B16/4-29, y por el contrario, realizó un negocio jurídico de compraventa con la sociedad INVERSIONES NEMASTE S.A., con domicilio principal en la ciudad de Bogotá, identificado con el NIT 9001450807 representada legalmente por el señor LUIS DARIO DIAZ AGUIRRE mayor de edad, identificado con la cédula de ciudadanía Nro. 79.514.492, domiciliado y residenciado en la ciudad de Bogotá, sobre el bien inmueble ubicado actualmente en la calle 37B sur Nro. 72J-87 denominado lote 2 de la manzana 124 de la Urbanización Carvajal, con la suscripción de la Escritura Pública 1299 del 11 de junio del 2010 de la Notaria 44 del Círculo de Bogotá, sobre el cual se originó el Folio de Matrícula Inmobiliaria 050S-40534648 Carvajal con fecha de apertura el 19 de septiembre del 2009. | O28: CARVAJAL | P28: N/A | Q28: N/A | R28: ZONA DE CESIÓN | S28: 26330 | T28: KENNEDY | U28: 43 MTS2 | V28: N/A | W28: N/A | X28: N/A | Y28: N/A | Z28: EN CURSO | AA28: EN CURSO | AB28: EN CURSO | AC28: ESTA EN TRAMITE DE ADMISION DE LA DEMANDA | AD28: EN CURSO | AE28: N/A | AF28: DESPACHO PARA RESOLVER RECURSO DE NAMASTE 08-04-2024
A29: 558364 | B29: CONTENCIOSO ADMINISTRATIVA | C29: 2016-00311 | D29: REPARACIÓN DIRECTA | E29: 42970 | F29: TRIBUNAL ADMINISTRATIVO DE CUNDINAMARCA SECCIÓN TERCERA | G29: JOAN SEBASTIAN MARQUEZ ROJAS | H29: JOSE GABRIEL BOSSA MARTINEZ | I29: DADEP - PLANEACIÓN - GOBIERNO - ALC USAQUEN - PLANEACIÓN - CATASTRO | J29: DIRECTA | K29: DEMANDADO | L29: REF SOLICITA SE DECLARE LA NATURALEZA JURIDICA PRIVADA DE LOS INMUEBLES HEXAGONALES CON NOMECLATURA N CARRERA 5 BIS N 127 A 09 Y OTROS , EN RAZON A QUE NO CONSTITUYEN BUP NI EP NI ZUP POR NO POSEER DICHO CARACTER. | M29: NA | N29: REF SOLICITA SE DECLARE LA NATURALEZA JURIDICA PRIVADA DE LOS INMUEBLES HEXAGONALES CON NOMECLATURA N CARRERA 5 BIS N 127 A 09 Y OTROS , EN RAZON A QUE NO CONSTITUYEN BUP NI EP NI ZUP POR NO POSEER DICHO CARACTER. | O29: N/A | P29: N/A | Q29: NA | R29: ZONA DE CESIÓN | S29: 110223 | T29: USAQUEN | U29: 472.82 | V29: NA | W29: NA | X29: 472.82 | Y29: 221,586,057,70 | Z29: 25/07/2024 | AA29: NA | AB29: NA | AC29: Apelación de Sentencia de primera instancia del 25 de julio de 2024 - Pronunciamiento al recurso de apelación. | AD29: EN CURSO | AE29: N/A | AF29: EN APELACIÓN DE SENTENCIA - PRONUNCIAMIENTO.
A30: 674820 | B30: PENAL | C30: 2021-55466 | D30: PENAL | E30: 44347 | F30: FISCALIA 96 SECCIONALUNIDAD FE PUBLICA Y ORDEN ECONOMICO - ORDINARIO | G30: JOSE AGUSTÍN AVENDAÑO | H30: DADEP | I30: INDETERMINADO/ FRANCISCO DANIEL GOMEZ ZULUAGA | J30: DIRECTA | K30: DENUNCIANTE | L30: FALSIFICACION FIRMA NADIME AMPARO YAVER LICHT | M30: FALSEDAD MATERIAL EN DOCUMENTO PÚBLICO, OBTENCIÓN DE DOCUMENTO PÚBLICO FALSO, FRAUDE PROCESAL | N30: FALSIFICACION FIRMA NADIME AMPARO YAVER LICHT EN LA NOTARIA 58 DE BOGOTÁ | O30: BARRIO LA MERCED | P30: N/A | Q30: N/A | R30: BIEN FISCAL | S30: 2-1817 | T30: BARRIOS UNIDOS | U30: N/A | V30: N/A | W30: N/A | X30: N/A | Y30: N/A | Z30: N/A | AA30: N/A | AB30: N/A | AC30: EL DÍA 4 DE MAYO LA FISCALÍA 96 SECCIONAL DRA. MARÍA SARMIENTO, EMITE ÓRDENES A PJ, Y UN OFICIO CON DESTINO A LA OFICINA DE INSTRUMENTOS PÚBLICOS INFORMANDO QUE EL PREDIO CON MATRÍCULA INMOBILIARIA 50C-1791850 ES UN PREDIO DEL DISTRITO EN EL CUAL CURSA INVESTIGACION, EL DÍA 19 DE FEBRERO DE 2024 SE ASISTE A LA FISCALÍA 96 SECCIONAL DE BOGOTÁ, INFORMA EL DESPACHO QUE SE CONTINUA CON LA EVACUACIÓN DE ÓRDENES A PJ DE LO CUAL SE AGENDA REUNIÓN PARA EL DÍA 28 DE FEBRERO A LAS 3 PM, SE SOLICITO AUDIENCIA ANTE JUEZ PENAL DE CONTROL DE GARANTÍAS RESPECTO A LA SUSPENSIÓN DEL PODER DISPOSITIVO DEL INMUEBLE CON MATRÍCULA INMOBILIARIA 50C-1791850, AUDIENCIA FIJADA EL DÍA 19 DE MARZO A LAS 11 AM | AD30: EN CURSO | AE30: N/A | AF30: INDAGACIÓN PRELIMINAR
A31: 359396 | B31: CONSTITUCIONAL | C31: 2010-00522 | D31: ACCION POPULAR | E31: 40431 | F31: JUZGADO 6 CIVIL DEL CIRCUITO DE BOGOTÁ | G31: MARIA FERNANDA MADIEDO SANCHEZ | H31: DADEP | I31: CONSTRUCTORA AMG SA - CONSTRUCTORA BOLIVAR - INVERSIONES MAZUERA - HOSPITAL SAN CARLOS | J31: DIRECTA | K31: DEMANDADO | L31: ENTREGA ZONAS DE CESIÓN | M31: NA | N31: ENTREGA Y ESCRITURACION ZONAS DE CESION SAN CARLOS | O31: BOSQUE SAN CARLOS | P31: NA | Q31: NA | R31: ZONA DE CESIÓN | S31: 667 y 477-26 | T31: RAFAEL URIBE | U31: 41341 | V31: NA | W31: NA | X31: NA | Y31: NA | Z31: 41822 | AA31: 41983 | AB31: SIN ORDENES - DADEP EXIGIR DEMANDADO ENTREGA Y ESCRITURACION | AC31: Las ultimas actuaciones en el proceso por parte del juzgado sexto civil del circuito corresponde a que mediante auto del 14 de diciembre de 2021 manifiesta "Requerir a los intervinientes para que manifiesten lo que consideren correspondiente sobre la solicitud efectuada por la Fundación Hospital San Carlos y puesta en conocimiento en providencia del pasado 15 de julio. De otra parte, se requiere nuevamente al DADEP conforme lo ordenado en providencia del 26 de febrero de 2020 para que indique si ya dio cumplimiento total al fallo emitido dentro de esta acción que lleve a la finalización de este trámite". Tambien se evidencia en la rama judicial que el juzgado en la actuaciones del proceso publico que emitio un oficio requiriendo al DADEP con fecha 21 de febrero de 2022, pero se esta a la espera de la notificaciòn . Las acciones a seguir corresponde a elaborar memorando solicitando informaciòn a la Subdirecciòn de registro inmobiliario para saber en que estado se encuentra la RESTITUIR Y ESCRITURAR LAS ZONAS DE CESION. el dia 2-05-2022 se profiere un auto en donde se requiere a la sociedad de arquitectos por 10 dias para que informen sobre el adelantamiento dela entrega de las obras y/o informen sobre el plan de trabajo cronologico. se fija estado de fecha 2 de mayo de 2022, el 20 de Mayo de 2022 ingresa al despacho. auto de fecha 22 junio de 2022 pone en conocimiento el informe presentado por el urbanizador sobre el adelantamiento de las obras junto con el plan de trabajo cronologico con etapas y actvidades verificables, se cito a reunion por teams para seguimiento el dia 11 de agosto de 2022 de 4:00 a 5:00 pm. se remite informe de cumplimiento del fallo mediante orfeo 20221100152371 el dia 28 septiembre de 2022. auto de fecha 12-10-2022 despacho requiere se informe sobre gestiones adelantadas para la entrega de las zonas de cesion. mediante correo electronico de fecha 16-11 -2022 se solicita al despacho dar cumplimiento al auto de fecha 12-10-2022. Radicado orfeo 20222010165251 20-10-2022 SRI da anuencia sobre licencia de saneamiento, se solicita al urbanizador remitir copia de la licencia. El 26-1-2023 se remite correo a la apodera de CIGESA solicitando remitir lo solicitando mediante oficio 20222010165251 y se solicita informar de la situacion al despacho. EL 10 de marzo de 2023 se radica memorial al despacho informando sobre el cumplimiento de la accion popular, el proceso ingreso al despacho con esta solicitud desde el 14-3-2023. Mediante orfeo 20234000157102 aia informa sobre la radicacion ante la curaduria 5° de la licencia de urbanismo. se consulta web de la rama 27-7-2023 se emite respuesta juzgado 6 administrativo. Mediante correo de fecha 2-8-2023 se solicito informacion al apoyo técnico SRI sobre copia de la licencia de urbanismo y/o estado del tramite. el 24-8-2023 SRI remite oficio 20232010129071 al urbanizador. AUTO 15 NOVIEMBRE DE 2023 JUZGADO REQUIERE 5 DIAS PARA INFORME DE CUMPLIMIENTO. el 16-11-2023 mediante memorando 20231300041523 se solicita informe de cumplimiento a SRI. 21-11-2023 se descorre traslado al auto de fecha 15-11-2023. 01-02-2024 al despacho. 4-4-2024 IMPULSO PROCESAL, SEC ambiente da respuesta al urbanizador se remite copia al dadep. se revisa el proceso el 30-1-2025 proceso sin novedad procesal. | AD31: CON FALLO | AE31: SRI | AF31: CUMPLIMIENTO DE FALLO
